I'm sorry, but an uncaught exception occurred.

While running game code:
  File "game/script.rpy", line 27, in script
    e "You've created a new Ren'Py game."
Exception: Sayer 'e' is not defined.

-- Full Traceback ------------------------------------------------------------

Full traceback:
  File "game/script.rpy", line 27, in script
    e "You've created a new Ren'Py game."
  File "/Users/jonas/Code/Ren'Py/Ren'Py SDK/renpy/ast.py", line 2586, in execute
    Say.execute(self)
  File "/Users/jonas/Code/Ren'Py/Ren'Py SDK/renpy/ast.py", line 583, in execute
    who = eval_who(self.who, self.who_fast)
  File "/Users/jonas/Code/Ren'Py/Ren'Py SDK/renpy/ast.py", line 472, in eval_who
    raise Exception("Sayer '%s' is not defined." % who)
Exception: Sayer 'e' is not defined.

macOS-15.1.1-arm64-arm-64bit arm64
Ren'Py 8.3.7.25031702
Proyecto Final 1.0
Tue Apr  8 11:16:05 2025
